Workbook

Sheet Averaged Data
F1: Fixed sink and trim tests
F2: Average results from all runs | J2: Idea is to put one line of results in here from each test. | Q2: Models | T2: Dates | W2: Ref. Values
F3: Entered by RGJF, 22/10/13
Q4: V1 | R4: Rounded hull | T4: D1 | U4: 41457 | W4: A= | X4: 0.0488 | Y4: m2
Q5: V2 | R5: Wide Vee | T5: D2 | U5: 41458 | W5: rho= | X5: 1000 | Y5: kg/m3
Q6: V3 | R6: Narrow Vee | T6: D3 | U6: 41459
T7: D4 | U7: 41460
F10: Measured | G10: Measured | H10: Measured | I10: Measured | J10: Measured | K10: Measured | L10: Measured | M10: Time | N10: Comment | O10: Calc | P10: Calc | Q10: Calc | R10: Calc | V10: dynamic pressure | W10: coefts | X10: coefts | Y10: coefts | Z10: coefts
W11: Coefficients
A12: Day | B12: Model | C12: Test | D12: Yaw | E12: Speed | F12: Stbd Drag Force | G12: Port Drag Force | H12: FWD Side Force | I12: AFT Side Force | J12: Heave | K12: Pitch | L12: Velocity | O12: Total Drag | P12: Total Lift | Q12: Resistance | R12: Sideforce | V12: q [N/m2] | W12: CD | X12: CL | Y12: CR | Z12: CS
B13: shape | C13: number | D13: deg | E13: m/s | F13: N | G13: N | H13: N | I13: N | J13: mm | K13: deg | L13: m/s | O13: N | P13: N | Q13: N | R13: N
A15: D1 | B15: V1 | C15: 0 | D15: 0 | E15: 0 | F15: -41.144572 | G15: 10.981373 | H15: -1.1073181 | I15: -1.8280901 | J15: 29.720349 | K15: 2.5462509 | L15: 0 | N15: setup | O15: =F15+G15 -> -30.163199 | P15: =-(H15+I15) -> 2.9354082 | Q15: =O15*COS(RADIANS(D15))-P15*SIN(RADIANS(D15)) -> -30.163199 | R15: =(O15*SIN(RADIANS(D15)))+(P15*(COS(RADIANS(D15)))) -> 2.9354082 | V15: =0.5*$X$5*$L15^2 -> 0
A16: D1 | B16: V1 | C16: 1 | D16: 0 | E16: 0 | F16: -0.007420575 | G16: -0.015892855 | H16: 0.00762828 | I16: -0.003543639 | J16: 29.731363 | K16: 2.5434638 | L16: 0 | O16: =F16+G16 -> -0.02331343 | P16: =-(H16+I16) -> -0.004084641 | Q16: =O16*COS(RADIANS(D16))-P16*SIN(RADIANS(D16)) -> -0.02331343 | R16: =(O16*SIN(RADIANS(D16)))+(P16*(COS(RADIANS(D16)))) -> -0.004084641 | V16: =0.5*$X$5*$L16^2 -> 0
A17: D1 | B17: V1 | C17: 2 | D17: 0 | E17: 0.4 | F17: 0.01993211 | G17: -0.011704373 | H17: -0.019176398 | I17: -0.032089427 | J17: 29.737275 | K17: 2.5435509 | L17: 0.39915733 | O17: =F17+G17 -> 0.008227737 | P17: =-(H17+I17) -> 0.051265825 | Q17: =O17*COS(RADIANS(D17))-P17*SIN(RADIANS(D17)) -> 0.008227737 | R17: =(O17*SIN(RADIANS(D17)))+(P17*(COS(RADIANS(D17)))) -> 0.051265825 | V17: =0.5*$X$5*$L17^2 -> 79.663288 | W17: =$O17/($X$4*$V17) -> 0.0021164224 | X17: =$P17/($X$4*$V17) -> 0.013187118 | Y17: =$Q17/($X$4*$V17) -> 0.0021164224 | Z17: =$R17/($X$4*$V17) -> 0.013187118
A18: D1 | B18: V1 | C18: 3 | D18: 0 | E18: 0.4 | F18: 0.066094327 | G18: 0.033210193 | H18: 0.027715018 | I18: -0.000555214 | J18: 29.737275 | K18: 2.5444219 | L18: 0.39916652 | M18: 11.04 | N18: good run | O18: =F18+G18 -> 0.09930452 | P18: =-(H18+I18) -> -0.027159804 | Q18: =O18*COS(RADIANS(D18))-P18*SIN(RADIANS(D18)) -> 0.09930452 | R18: =(O18*SIN(RADIANS(D18)))+(P18*(COS(RADIANS(D18)))) -> -0.027159804 | V18: =0.5*$X$5*$L18^2 -> 79.666955 | W18: =$O18/($X$4*$V18) -> 0.025542946 | X18: =$P18/($X$4*$V18) -> -0.0069860002 | Y18: =$Q18/($X$4*$V18) -> 0.025542946 | Z18: =$R18/($X$4*$V18) -> -0.0069860002
A19: D1 | B19: V1 | C19: 4 | D19: 0 | E19: 0.8 | F19: 0.35686112 | G19: 0.15967484 | H19: 0.093275832 | I19: -0.058884459 | J19: 29.727557 | K19: 2.5452929 | L19: 0.80495266 | M19: 11.27 | O19: =F19+G19 -> 0.51653595 | P19: =-(H19+I19) -> -0.034391373 | Q19: =O19*COS(RADIANS(D19))-P19*SIN(RADIANS(D19)) -> 0.51653595 | R19: =(O19*SIN(RADIANS(D19)))+(P19*(COS(RADIANS(D19)))) -> -0.034391373 | V19: =0.5*$X$5*$L19^2 -> 323.97439 | W19: =$O19/($X$4*$V19) -> 0.032671573 | X19: =$P19/($X$4*$V19) -> -0.0021752992 | Y19: =$Q19/($X$4*$V19) -> 0.032671573 | Z19: =$R19/($X$4*$V19) -> -0.0021752992
A20: D1 | B20: V1 | C20: 5 | D20: 0 | E20: 1.2 | F20: 0.9551765 | G20: 0.65989715 | H20: 0.23749547 | I20: -0.047688969 | J20: 29.725532 | K20: 2.5442477 | L20: 1.1953708 | M20: 11.5 | N20: Originally didn't change file name before run. Recovered | O20: =F20+G20 -> 1.6150736 | P20: =-(H20+I20) -> -0.1898065 | Q20: =O20*COS(RADIANS(D20))-P20*SIN(RADIANS(D20)) -> 1.6150736 | R20: =(O20*SIN(RADIANS(D20)))+(P20*(COS(RADIANS(D20)))) -> -0.1898065 | V20: =0.5*$X$5*$L20^2 -> 714.45565 | W20: =$O20/($X$4*$V20) -> 0.04632306 | X20: =$P20/($X$4*$V20) -> -0.0054439734 | Y20: =$Q20/($X$4*$V20) -> 0.04632306 | Z20: =$R20/($X$4*$V20) -> -0.0054439734
A21: D1 | B21: V1 | C21: -6 | D21: 0 | E21: 1.6 | F21: -39.728019 | G21: 12.215801 | H21: -0.74748255 | I21: -1.8159352 | J21: 29.721145 | K21: 2.5475163 | L21: 1.6031259 | M21: 12.24 | N21: Big bow wave(over model). Set model now to 4degs | O21: =F21+G21 -> -27.512218 | P21: =-(H21+I21) -> 2.5634177 | Q21: =O21*COS(RADIANS(D21))-P21*SIN(RADIANS(D21)) -> -27.512218 | R21: =(O21*SIN(RADIANS(D21)))+(P21*(COS(RADIANS(D21)))) -> 2.5634177 | V21: =0.5*$X$5*$L21^2 -> 1285.0063 | W21: =$O21/($X$4*$V21) -> -0.43873322 | X21: =$P21/($X$4*$V21) -> 0.040878439 | Y21: =$Q21/($X$4*$V21) -> -0.43873322 | Z21: =$R21/($X$4*$V21) -> 0.040878439
A22: D1 | B22: V1 | C22: 6 | D22: 0 | E22: 1.6 | F22: 1.3497232 | G22: 1.1369198 | H22: 0.32989374 | I22: 0.00249978 | J22: 29.712471 | K22: 2.5437002 | L22: 1.605672 | M22: ~14.35 | N22: re-run of test 6 to confirm bow over the top. From now on only test to 1.2m/s.This test done after test 10 | O22: =F22+G22 -> 2.4866431 | P22: =-(H22+I22) -> -0.33239352 | Q22: =O22*COS(RADIANS(D22))-P22*SIN(RADIANS(D22)) -> 2.4866431 | R22: =(O22*SIN(RADIANS(D22)))+(P22*(COS(RADIANS(D22)))) -> -0.33239352 | V22: =0.5*$X$5*$L22^2 -> 1289.0913 | W22: =$O22/($X$4*$V22) -> 0.039528465 | X22: =$P22/($X$4*$V22) -> -0.0052838326 | Y22: =$Q22/($X$4*$V22) -> 0.039528465 | Z22: =$R22/($X$4*$V22) -> -0.0052838326
A23: D1 | B23: V1 | C23: 7 | D23: 4 | E23: 0 | F23: 0.007952066 | G23: 0.016075913 | H23: -0.041631306 | I23: 0.016316026 | J23: 29.713141 | K23: 2.5413735 | L23: 0 | M23: 13.05 | N23: zero test. Small vibrations of model | O23: =F23+G23 -> 0.024027979 | P23: =-(H23+I23) -> 0.02531528 | Q23: =O23*COS(RADIANS(D23))-P23*SIN(RADIANS(D23)) -> 0.022203543 | R23: =(O23*SIN(RADIANS(D23)))+(P23*(COS(RADIANS(D23)))) -> 0.02692972 | V23: =0.5*$X$5*$L23^2 -> 0 | W23: =$O23/($X$4*$V23) -> #DIV/0! | X23: =$P23/($X$4*$V23) -> #DIV/0! | Y23: =$Q23/($X$4*$V23) -> #DIV/0! | Z23: =$R23/($X$4*$V23) -> #DIV/0!
A24: D1 | B24: V1 | C24: 8 | D24: 4 | E24: 0.4 | F24: -0.02375298 | G24: 0.083425445 | H24: -0.069434029 | I24: 0.061104023 | J24: 29.71549 | K24: 2.5423316 | L24: 0.40036896 | M24: 13.25 | O24: =F24+G24 -> 0.059672465 | P24: =-(H24+I24)-$P18 -> 0.03548981 | Q24: =O24*COS(RADIANS(D24))-P24*SIN(RADIANS(D24)) -> 0.057051462 | R24: =(O24*SIN(RADIANS(D24)))+(P24*(COS(RADIANS(D24)))) -> 0.039565899 | V24: =0.5*$X$5*$L24^2 -> 80.147652 | W24: =$O24/($X$4*$V24) -> 0.015256796 | X24: =$P24/($X$4*$V24) -> 0.0090738803 | Y24: =$Q24/($X$4*$V24) -> 0.01458667 | Z24: =$R24/($X$4*$V24) -> 0.010116037
A25: D1 | B25: V1 | C25: 9 | D25: 4 | E25: 0.8 | F25: -0.019295436 | G25: 0.56600487 | H25: -0.23174503 | I25: 0.20889253 | J25: 29.712574 | K25: 2.5452929 | L25: 0.80652782 | M25: 13.4 | O25: =F25+G25 -> 0.54670944 | P25: =-(H25+I25)-$P19 -> 0.057243871 | Q25: =O25*COS(RADIANS(D25))-P25*SIN(RADIANS(D25)) -> 0.54138455 | R25: =(O25*SIN(RADIANS(D25)))+(P25*(COS(RADIANS(D25)))) -> 0.09524095 | V25: =0.5*$X$5*$L25^2 -> 325.24356 | W25: =$O25/($X$4*$V25) -> 0.034445147 | X25: =$P25/($X$4*$V25) -> 0.0036066206 | Y25: =$Q25/($X$4*$V25) -> 0.034109655 | Z25: =$R25/($X$4*$V25) -> 0.0060006071
A26: D1 | B26: V1 | C26: 10 | D26: 4 | E26: 1.6 | F26: 0.069466882 | G26: 2.6037486 | H26: -1.0951052 | I26: 0.72602649 | J26: 29.717892 | K26: 2.5447602 | L26: 1.6057728 | M26: 14.02 | N26: large (or nice) wake pattern | O26: =F26+G26 -> 2.6732155 | P26: =-(H26+I26)-P22 -> 0.70147219 | Q26: =O26*COS(RADIANS(D26))-P26*SIN(RADIANS(D26)) -> 2.6177715 | R26: =(O26*SIN(RADIANS(D26)))+(P26*(COS(RADIANS(D26)))) -> 0.88623752 | V26: =0.5*$X$5*$L26^2 -> 1289.2531 | W26: =$O26/($X$4*$V26) -> 0.042488945 | X26: =$P26/($X$4*$V26) -> 0.011149424 | Y26: =$Q26/($X$4*$V26) -> 0.0416077 | Z26: =$R26/($X$4*$V26) -> 0.014086144
A27: D1 | B27: V1 | C27: 11 | D27: 4 | E27: 1.2 | F27: 0.25006797 | G27: 1.4872121 | H27: -0.57341495 | I27: 0.33016629 | J27: 29.71055 | K27: 2.5440735 | L27: 1.1985548 | M27: 15.14 | N27: After set to 8deg | O27: =F27+G27 -> 1.73728 | P27: =-(H27+I27) -> 0.24324865 | Q27: =O27*COS(RADIANS(D27))-P27*SIN(RADIANS(D27)) -> 1.7160799 | R27: =(O27*SIN(RADIANS(D27)))+(P27*(COS(RADIANS(D27)))) -> 0.36384264 | V27: =0.5*$X$5*$L27^2 -> 718.26678 | W27: =$O27/($X$4*$V27) -> 0.049563757 | X27: =$P27/($X$4*$V27) -> 0.0069397662 | Y27: =$Q27/($X$4*$V27) -> 0.048958929 | Z27: =$R27/($X$4*$V27) -> 0.010380254
A28: D1 | B28: V1 | C28: 12 | D28: 8 | E28: 0.4 | F28: -0.013495438 | G28: 0.23512774 | H28: -0.098655558 | I28: 0.082243898 | J28: 29.711926 | K28: 2.5410251 | L28: 0.39705455 | M28: 15.4 | O28: =F28+G28 -> 0.2216323 | P28: =-(H28+I28)-$P18 -> 0.043571464 | Q28: =O28*COS(RADIANS(D28))-P28*SIN(RADIANS(D28)) -> 0.21341142 | R28: =(O28*SIN(RADIANS(D28)))+(P28*(COS(RADIANS(D28)))) -> 0.073992684 | V28: =0.5*$X$5*$L28^2 -> 78.826159 | W28: =$O28/($X$4*$V28) -> 0.057615969 | X28: =$P28/($X$4*$V28) -> 0.011326923 | Y28: =$Q28/($X$4*$V28) -> 0.055478851 | Z28: =$R28/($X$4*$V28) -> 0.019235284
A29: D1 | B29: V1 | C29: 13 | D29: 8 | E29: 0.8 | F29: -0.27818868 | G29: 0.88052106 | H29: -0.52998282 | I29: 0.3462149 | J29: 29.710793 | K29: 2.537367 | L29: 0.80848332 | M29: 15.53 | N29: photographed | O29: =F29+G29 -> 0.60233237 | P29: =-(H29+I29)-$P19 -> 0.21815929 | Q29: =O29*COS(RADIANS(D29))-P29*SIN(RADIANS(D29)) -> 0.56610861 | R29: =(O29*SIN(RADIANS(D29)))+(P29*(COS(RADIANS(D29)))) -> 0.29986464 | V29: =0.5*$X$5*$L29^2 -> 326.82264 | W29: =$O29/($X$4*$V29) -> 0.037766284 | X29: =$P29/($X$4*$V29) -> 0.013678603 | Y29: =$Q29/($X$4*$V29) -> 0.035495051 | Z29: =$R29/($X$4*$V29) -> 0.018801535
A30: D1 | B30: V1 | C30: 14 | D30: 8 | E30: 1.2 | F30: -0.34372929 | G30: 2.1691678 | H30: -1.3325912 | I30: 0.55141121 | J30: 29.71144 | K30: 2.5420703 | L30: 1.1940426 | M30: 14.29 | N30: photo again. Strange time. Probably 16.29 | O30: =F30+G30 -> 1.8254385 | P30: =-(H30+I30)-$P20 -> 0.97098647 | Q30: =O30*COS(RADIANS(D30))-P30*SIN(RADIANS(D30)) -> 1.6725382 | R30: =(O30*SIN(RADIANS(D30)))+(P30*(COS(RADIANS(D30)))) -> 1.2155888 | V30: =0.5*$X$5*$L30^2 -> 712.86882 | W30: =$O30/($X$4*$V30) -> 0.052473225 | X30: =$P30/($X$4*$V30) -> 0.027911536 | Y30: =$Q30/($X$4*$V30) -> 0.048078024 | Z30: =$R30/($X$4*$V30) -> 0.034942764
A31: D2 | B31: V1 | C31: 1 | D31: 8 | E31: 1.2 | F31: 1.9344262 | G31: -0.55381301 | H31: 1.4722661 | I31: -0.45231331 | J31: 29.722714 | K31: 2.5286184 | L31: 1.1942638 | N31: Ian skimmed tank before tests. Previous test with model rotated bow to port, following tests with bow rotated to starboard. Data recorded for only 5 sec, not 10 sec. After set to 16 degs | O31: =F31+G31 -> 1.3806132 | P31: =H31+I31+$P20 -> 0.83014633 | Q31: =O31*COS(RADIANS(D31))-P31*SIN(RADIANS(D31)) -> 1.2516432 | R31: =(O31*SIN(RADIANS(D31)))+(P31*(COS(RADIANS(D31)))) -> 1.0142116 | V31: =0.5*$X$5*$L31^2 -> 713.13304 | W31: =$O31/($X$4*$V31) -> 0.039671776 | X31: =$P31/($X$4*$V31) -> 0.023854168 | Y31: =$Q31/($X$4*$V31) -> 0.035965835 | Z31: =$R31/($X$4*$V31) -> 0.029143265
A32: D2 | B32: V1 | C32: 2 | D32: 16 | E32: 0.4 | F32: 0.22162008 | G32: -0.1023417 | H32: 0.2825125 | I32: 0.01396965 | J32: 29.721966 | K32: 2.5239516 | L32: 0.39916287 | N32: Data recorded for only 5 sec, not 10 sec. Video + photo | O32: =F32+G32 -> 0.11927838 | P32: =H32+I32 -> 0.29648215 | Q32: =O32*COS(RADIANS(D32))-P32*SIN(RADIANS(D32)) -> 0.032936177 | R32: =(O32*SIN(RADIANS(D32)))+(P32*(COS(RADIANS(D32)))) -> 0.31787451 | V32: =0.5*$X$5*$L32^2 -> 79.665499 | W32: =$O32/($X$4*$V32) -> 0.030681148 | X32: =$P32/($X$4*$V32) -> 0.076262045 | Y32: =$Q32/($X$4*$V32) -> 0.0084719443 | Z32: =$R32/($X$4*$V32) -> 0.081764653
A33: D2 | B33: V1 | C33: 3 | D33: 16 | E33: 0.8 | F33: 1.1883121 | G33: -0.70034065 | H33: 1.0867103 | I33: -0.34302579 | J33: 29.718081 | K33: 2.5276122 | L33: 0.80877014 | M33: 10.35 | N33: Data recorded for 10 sec. Ran again to check recording was working properly. Seemed ok | O33: =F33+G33 -> 0.48797141 | P33: =H33+I33 -> 0.7436845 | Q33: =O33*COS(RADIANS(D33))-P33*SIN(RADIANS(D33)) -> 0.26408099 | R33: =(O33*SIN(RADIANS(D33)))+(P33*(COS(RADIANS(D33)))) -> 0.84937858 | V33: =0.5*$X$5*$L33^2 -> 327.05457 | W33: =$O33/($X$4*$V33) -> 0.030574145 | X33: =$P33/($X$4*$V33) -> 0.046596005 | Y33: =$Q33/($X$4*$V33) -> 0.016546155 | Z33: =$R33/($X$4*$V33) -> 0.053218331
A34: D2 | B34: V1 | C34: 4 | D34: 16 | E34: 1.2 | F34: 3.3276295 | G34: -1.32221 | H34: 2.8252796 | I34: -0.73651262 | J34: 29.717029 | K34: 2.5282219 | L34: 1.1962005 | M34: 11.05 | O34: =F34+G34 -> 2.0054195 | P34: =H34+I34 -> 2.088767 | Q34: =O34*COS(RADIANS(D34))-P34*SIN(RADIANS(D34)) -> 1.3519908 | R34: =(O34*SIN(RADIANS(D34)))+(P34*(COS(RADIANS(D34)))) -> 2.5606203 | V34: =0.5*$X$5*$L34^2 -> 715.44785 | W34: =$O34/($X$4*$V34) -> 0.057439075 | X34: =$P34/($X$4*$V34) -> 0.059826307 | Y34: =$Q34/($X$4*$V34) -> 0.038723617 | Z34: =$R34/($X$4*$V34) -> 0.073341092
A35: D2 | B35: V1 | C35: 5 | D35: 24 | E35: 0.4 | F35: 0.43555385 | G35: -0.12871858 | H35: 0.49993948 | I35: 0.061137141 | J35: 29.714518 | K35: 2.5283961 | L35: 0.40077542 | M35: 11.36 | O35: =F35+G35 -> 0.30683526 | P35: =H35+I35 -> 0.56107662 | Q35: =O35*COS(RADIANS(D35))-P35*SIN(RADIANS(D35)) -> 0.052097542 | R35: =(O35*SIN(RADIANS(D35)))+(P35*(COS(RADIANS(D35)))) -> 0.63737014 | V35: =0.5*$X$5*$L35^2 -> 80.310467 | W35: =$O35/($X$4*$V35) -> 0.078291263 | X35: =$P35/($X$4*$V35) -> 0.1431628 | Y35: =$Q35/($X$4*$V35) -> 0.013293069 | Z35: =$R35/($X$4*$V35) -> 0.16262966
A36: D2 | B36: V1 | C36: 6 | D36: 24 | E36: 0.8 | F36: 1.8806858 | G36: -0.84036618 | H36: 1.6905368 | I36: -0.4161805 | J36: 29.712007 | K36: 2.5250864 | L36: 0.80715357 | M36: 12.04 | O36: =F36+G36 -> 1.0403196 | P36: =H36+I36 -> 1.2743563 | Q36: =O36*COS(RADIANS(D36))-P36*SIN(RADIANS(D36)) -> 0.43205185 | R36: =(O36*SIN(RADIANS(D36)))+(P36*(COS(RADIANS(D36)))) -> 1.5873185 | V36: =0.5*$X$5*$L36^2 -> 325.74845 | W36: =$O36/($X$4*$V36) -> 0.065443211 | X36: =$P36/($X$4*$V36) -> 0.080165718 | Y36: =$Q36/($X$4*$V36) -> 0.027179014 | Z36: =$R36/($X$4*$V36) -> 0.099853179
A37: D2 | B37: V1 | C37: 7 | D37: 24 | E37: 1.2 | F37: 4.6290384 | G37: -1.8179316 | H37: 4.0901864 | I37: -0.85066085 | J37: 29.715166 | K37: 2.5304864 | L37: 1.196084 | M37: 12.3 | N37: waterline well below on leeward side. | O37: =F37+G37 -> 2.8111068 | P37: =H37+I37 -> 3.2395256 | Q37: =O37*COS(RADIANS(D37))-P37*SIN(RADIANS(D37)) -> 1.2504401 | R37: =(O37*SIN(RADIANS(D37)))+(P37*(COS(RADIANS(D37)))) -> 4.102834 | V37: =0.5*$X$5*$L37^2 -> 715.30843 | W37: =$O37/($X$4*$V37) -> 0.080531203 | X37: =$P37/($X$4*$V37) -> 0.092804331 | Y37: =$Q37/($X$4*$V37) -> 0.035821992 | Z37: =$R37/($X$4*$V37) -> 0.11753597
N38: Lunch. Put new model in. Lowered model in tank to get correct waterline. Also adjusted for yaw. Note U-model had +ve sideforce @ 0AoA indicating slight yaw or assymetry
A39: D2 | B39: V2 | C39: 1 | D39: 0 | E39: 0.4 | F39: 0.022096626 | G39: 0.005697571 | H39: 0.00740716 | I39: 0.010741308 | J39: 25.708994 | K39: 2.5307477 | L39: 0.39910058 | M39: 13.58 | O39: =F39+G39 -> 0.027794197 | P39: =H39+I39 -> 0.018148468 | Q39: =O39*COS(RADIANS(D39))-P39*SIN(RADIANS(D39)) -> 0.027794197 | R39: =(O39*SIN(RADIANS(D39)))+(P39*(COS(RADIANS(D39)))) -> 0.018148468 | V39: =0.5*$X$5*$L39^2 -> 79.640636 | W39: =$O39/($X$4*$V39) -> 0.0071515402 | X39: =$P39/($X$4*$V39) -> 0.0046696618 | Y39: =$Q39/($X$4*$V39) -> 0.0071515402 | Z39: =$R39/($X$4*$V39) -> 0.0046696618
A40: D2 | B40: V2 | C40: 2 | D40: 0 | E40: 0.8 | F40: 0.2537008 | G40: 0.17898591 | H40: 0.057258578 | I40: -0.011302624 | J40: 25.711423 | K40: 2.5282219 | L40: 0.80760298 | M40: 14.1 | O40: =F40+G40 -> 0.43268671 | P40: =H40+I40 -> 0.045955954 | Q40: =O40*COS(RADIANS(D40))-P40*SIN(RADIANS(D40)) -> 0.43268671 | R40: =(O40*SIN(RADIANS(D40)))+(P40*(COS(RADIANS(D40)))) -> 0.045955954 | V40: =0.5*$X$5*$L40^2 -> 326.11128 | W40: =$O40/($X$4*$V40) -> 0.027188666 | X40: =$P40/($X$4*$V40) -> 0.002887727 | Y40: =$Q40/($X$4*$V40) -> 0.027188666 | Z40: =$R40/($X$4*$V40) -> 0.002887727
A41: D2 | B41: V2 | C41: 3 | D41: 0 | E41: 1.2 | F41: 0.49040507 | G41: 0.3342724 | H41: 0.13229121 | I41: -0.018367569 | J41: 25.706726 | K41: 2.5298767 | L41: 1.1963631 | M41: 14.27 | O41: =F41+G41 -> 0.82467747 | P41: =H41+I41 -> 0.11392364 | Q41: =O41*COS(RADIANS(D41))-P41*SIN(RADIANS(D41)) -> 0.82467747 | R41: =(O41*SIN(RADIANS(D41)))+(P41*(COS(RADIANS(D41)))) -> 0.11392364 | V41: =0.5*$X$5*$L41^2 -> 715.64233 | W41: =$O41/($X$4*$V41) -> 0.023613931 | X41: =$P41/($X$4*$V41) -> 0.0032621056 | Y41: =$Q41/($X$4*$V41) -> 0.023613931 | Z41: =$R41/($X$4*$V41) -> 0.0032621056
A42: D2 | B42: V2 | C42: 4 | D42: 0 | E42: 1.6 | F42: 0.681884 | G42: 0.55797235 | H42: 0.19022795 | I42: -0.010908772 | J42: 25.707095 | K42: 2.5265951 | L42: 1.6066749 | M42: 14.56 | O42: =F42+G42 -> 1.2398563 | P42: =H42+I42 -> 0.17931918 | Q42: =O42*COS(RADIANS(D42))-P42*SIN(RADIANS(D42)) -> 1.2398563 | R42: =(O42*SIN(RADIANS(D42)))+(P42*(COS(RADIANS(D42)))) -> 0.17931918 | V42: =0.5*$X$5*$L42^2 -> 1290.7021 | W42: =$O42/($X$4*$V42) -> 0.019684552 | X42: =$P42/($X$4*$V42) -> 0.002846957 | Y42: =$Q42/($X$4*$V42) -> 0.019684552 | Z42: =$R42/($X$4*$V42) -> 0.002846957
A43: D2 | B43: V2 | C43: 5 | D43: 8 | E43: 0.4 | F43: 0.12175135 | G43: -0.059011372 | H43: 0.17142281 | I43: 0.031069468 | J43: 25.702353 | K43: 2.5248251 | L43: 0.40032756 | M43: 15.33 | O43: =F43+G43 -> 0.06273998 | P43: =H43+I43 -> 0.20249228 | Q43: =O43*COS(RADIANS(D43))-P43*SIN(RADIANS(D43)) -> 0.03394792 | R43: =(O43*SIN(RADIANS(D43)))+(P43*(COS(RADIANS(D43)))) -> 0.20925336 | V43: =0.5*$X$5*$L43^2 -> 80.131078 | W43: =$O43/($X$4*$V43) -> 0.016044403 | X43: =$P43/($X$4*$V43) -> 0.051783055 | Y43: =$Q43/($X$4*$V43) -> 0.0086814519 | Z43: =$R43/($X$4*$V43) -> 0.053512055
...

Sheet Results vs speed
A1: Edited 23/10/13, 24/10/13 | P1: U | Q1: V1 | R1: V2
A2: Edited 22/8/22 by RF for submission to JST. V1,2,3 changed to U, V1, V2 | L2: 0° | P2: =P$1&", "&$L2 -> U, 0° | Q2: =Q$1&", "&$L2 -> V1, 0° | R2: =R$1&", "&$L2 -> V2, 0°
L3: 4° | P3: =P$1&", "&$L3 -> U, 4° | Q3: =Q$1&", "&$L3 -> V1, 4° | R3: =R$1&", "&$L3 -> V2, 4°
A4: Note dummy yellow rows inserted to keep legend ordered | L4: 8° | P4: =P$1&", "&$L4 -> U, 8° | Q4: =Q$1&", "&$L4 -> V1, 8° | R4: =R$1&", "&$L4 -> V2, 8°
L5: 12° | P5: =P$1&", "&$L5 -> U, 12° | Q5: =Q$1&", "&$L5 -> V1, 12° | R5: =R$1&", "&$L5 -> V2, 12°
L6: 16° | P6: =P$1&", "&$L6 -> U, 16° | Q6: =Q$1&", "&$L6 -> V1, 16° | R6: =R$1&", "&$L6 -> V2, 16°
L7: 24° | P7: =P$1&", "&$L7 -> U, 24° | Q7: =Q$1&", "&$L7 -> V1, 24° | R7: =R$1&", "&$L7 -> V2, 24°
J10: ='Averaged Data'!J10 -> Measured | K10: ='Averaged Data'!K10 -> Measured | L10: ='Averaged Data'!L10 -> Measured | M10: ='Averaged Data'!M10 -> Time | N10: ='Averaged Data'!N10 -> Comment | O10: ='Averaged Data'!O10 -> Calc | P10: ='Averaged Data'!P10 -> Calc | Q10: ='Averaged Data'!Q10 -> Calc | R10: ='Averaged Data'!R10 -> Calc | V10: ='Averaged Data'!V10 -> dynamic pressure | W10: ='Averaged Data'!W10 -> coefts | X10: ='Averaged Data'!X10 -> coefts | Y10: ='Averaged Data'!Y10 -> coefts | Z10: ='Averaged Data'!Z10 -> coefts
W11: ='Averaged Data'!W11 -> Coefficients
A12: ='Averaged Data'!A12 -> Day | B12: ='Averaged Data'!B12 -> Model | C12: ='Averaged Data'!C12 -> Test | D12: ='Averaged Data'!D12 -> Yaw | E12: ='Averaged Data'!E12 -> Speed | J12: ='Averaged Data'!J12 -> Heave | K12: ='Averaged Data'!K12 -> Pitch | L12: ='Averaged Data'!L12 -> Velocity | O12: ='Averaged Data'!O12 -> Total Drag | P12: ='Averaged Data'!P12 -> Total Lift | Q12: ='Averaged Data'!Q12 -> Resistance | R12: ='Averaged Data'!R12 -> Sideforce | V12: ='Averaged Data'!V12 -> q [N/m2] | W12: ='Averaged Data'!W12 -> CD | X12: ='Averaged Data'!X12 -> CL | Y12: ='Averaged Data'!Y12 -> CR | Z12: ='Averaged Data'!Z12 -> CS
A13: ='Averaged Data'!A13 -> 0 | B13: ='Averaged Data'!B13 -> shape | C13: ='Averaged Data'!C13 -> number | D13: ='Averaged Data'!D13 -> deg | E13: ='Averaged Data'!E13 -> m/s | J13: ='Averaged Data'!J13 -> mm | K13: ='Averaged Data'!K13 -> deg | L13: ='Averaged Data'!L13 -> m/s | O13: ='Averaged Data'!O13 -> N | P13: ='Averaged Data'!P13 -> N | Q13: ='Averaged Data'!Q13 -> N | R13: ='Averaged Data'!R13 -> N
A15: ='Averaged Data'!A17 -> D1 | B15: ='Averaged Data'!B17 -> V1 | C15: ='Averaged Data'!C17 -> 2 | D15: ='Averaged Data'!D17 -> 0 | E15: ='Averaged Data'!E17 -> 0.4 | J15: ='Averaged Data'!J17 -> 29.737275 | K15: ='Averaged Data'!K17 -> 2.5435509 | L15: ='Averaged Data'!L17 -> 0.39915733 | M15: ='Averaged Data'!M17 -> 0 | N15: ='Averaged Data'!N17 -> 0 | O15: ='Averaged Data'!O17 -> 0.008227737 | P15: ='Averaged Data'!P17 -> 0.051265825 | Q15: ='Averaged Data'!Q17 -> 0.008227737 | R15: ='Averaged Data'!R17 -> 0.051265825 | V15: ='Averaged Data'!V17 -> 79.663288 | W15: ='Averaged Data'!W17 -> 0.0021164224 | X15: ='Averaged Data'!X17 -> 0.013187118 | Y15: ='Averaged Data'!Y17 -> 0.0021164224 | Z15: ='Averaged Data'!Z17 -> 0.013187118
A16: ='Averaged Data'!A18 -> D1 | B16: ='Averaged Data'!B18 -> V1 | C16: ='Averaged Data'!C18 -> 3 | D16: ='Averaged Data'!D18 -> 0 | E16: ='Averaged Data'!E18 -> 0.4 | J16: ='Averaged Data'!J18 -> 29.737275 | K16: ='Averaged Data'!K18 -> 2.5444219 | L16: ='Averaged Data'!L18 -> 0.39916652 | M16: ='Averaged Data'!M18 -> 11.04 | N16: ='Averaged Data'!N18 -> good run | O16: ='Averaged Data'!O18 -> 0.09930452 | P16: ='Averaged Data'!P18 -> -0.027159804 | Q16: ='Averaged Data'!Q18 -> 0.09930452 | R16: ='Averaged Data'!R18 -> -0.027159804 | V16: ='Averaged Data'!V18 -> 79.666955 | W16: ='Averaged Data'!W18 -> 0.025542946 | X16: ='Averaged Data'!X18 -> -0.0069860002 | Y16: ='Averaged Data'!Y18 -> 0.025542946 | Z16: ='Averaged Data'!Z18 -> -0.0069860002
A17: ='Averaged Data'!A19 -> D1 | B17: ='Averaged Data'!B19 -> V1 | C17: ='Averaged Data'!C19 -> 4 | D17: ='Averaged Data'!D19 -> 0 | E17: ='Averaged Data'!E19 -> 0.8 | J17: ='Averaged Data'!J19 -> 29.727557 | K17: ='Averaged Data'!K19 -> 2.5452929 | L17: ='Averaged Data'!L19 -> 0.80495266 | M17: ='Averaged Data'!M19 -> 11.27 | N17: ='Averaged Data'!N19 -> 0 | O17: ='Averaged Data'!O19 -> 0.51653595 | P17: ='Averaged Data'!P19 -> -0.034391373 | Q17: ='Averaged Data'!Q19 -> 0.51653595 | R17: ='Averaged Data'!R19 -> -0.034391373 | V17: ='Averaged Data'!V19 -> 323.97439 | W17: ='Averaged Data'!W19 -> 0.032671573 | X17: ='Averaged Data'!X19 -> -0.0021752992 | Y17: ='Averaged Data'!Y19 -> 0.032671573 | Z17: ='Averaged Data'!Z19 -> -0.0021752992
A18: ='Averaged Data'!A20 -> D1 | B18: ='Averaged Data'!B20 -> V1 | C18: ='Averaged Data'!C20 -> 5 | D18: ='Averaged Data'!D20 -> 0 | E18: ='Averaged Data'!E20 -> 1.2 | J18: ='Averaged Data'!J20 -> 29.725532 | K18: ='Averaged Data'!K20 -> 2.5442477 | L18: ='Averaged Data'!L20 -> 1.1953708 | M18: ='Averaged Data'!M20 -> 11.5 | N18: ='Averaged Data'!N20 -> Originally didn't change file name before run. Recovered | O18: ='Averaged Data'!O20 -> 1.6150736 | P18: ='Averaged Data'!P20 -> -0.1898065 | Q18: ='Averaged Data'!Q20 -> 1.6150736 | R18: ='Averaged Data'!R20 -> -0.1898065 | V18: ='Averaged Data'!V20 -> 714.45565 | W18: ='Averaged Data'!W20 -> 0.04632306 | X18: ='Averaged Data'!X20 -> -0.0054439734 | Y18: ='Averaged Data'!Y20 -> 0.04632306 | Z18: ='Averaged Data'!Z20 -> -0.0054439734
A19: ='Averaged Data'!A22 -> D1 | B19: ='Averaged Data'!B22 -> V1 | C19: ='Averaged Data'!C22 -> 6 | D19: ='Averaged Data'!D22 -> 0 | E19: ='Averaged Data'!E22 -> 1.6 | J19: ='Averaged Data'!J22 -> 29.712471 | K19: ='Averaged Data'!K22 -> 2.5437002 | L19: ='Averaged Data'!L22 -> 1.605672 | M19: ='Averaged Data'!M22 -> ~14.35 | N19: ='Averaged Data'!N22 -> re-run of test 6 to confirm bow over the top. From now on only test to 1.2m/s.This test done after test 10 | O19: ='Averaged Data'!O22 -> 2.4866431 | P19: ='Averaged Data'!P22 -> -0.33239352 | Q19: ='Averaged Data'!Q22 -> 2.4866431 | R19: ='Averaged Data'!R22 -> -0.33239352 | V19: ='Averaged Data'!V22 -> 1289.0913 | W19: ='Averaged Data'!W22 -> 0.039528465 | X19: ='Averaged Data'!X22 -> -0.0052838326 | Y19: ='Averaged Data'!Y22 -> 0.039528465 | Z19: ='Averaged Data'!Z22 -> -0.0052838326
A20: ='Averaged Data'!A24 -> D1 | B20: ='Averaged Data'!B24 -> V1 | C20: ='Averaged Data'!C24 -> 8 | D20: ='Averaged Data'!D24 -> 4 | E20: ='Averaged Data'!E24 -> 0.4 | J20: ='Averaged Data'!J24 -> 29.71549 | K20: ='Averaged Data'!K24 -> 2.5423316 | L20: ='Averaged Data'!L24 -> 0.40036896 | M20: ='Averaged Data'!M24 -> 13.25 | N20: ='Averaged Data'!N24 -> 0 | O20: ='Averaged Data'!O24 -> 0.059672465 | P20: ='Averaged Data'!P24 -> 0.03548981 | Q20: ='Averaged Data'!Q24 -> 0.057051462 | R20: ='Averaged Data'!R24 -> 0.039565899 | V20: ='Averaged Data'!V24 -> 80.147652 | W20: ='Averaged Data'!W24 -> 0.015256796 | X20: ='Averaged Data'!X24 -> 0.0090738803 | Y20: ='Averaged Data'!Y24 -> 0.01458667 | Z20: ='Averaged Data'!Z24 -> 0.010116037
A21: ='Averaged Data'!A25 -> D1 | B21: ='Averaged Data'!B25 -> V1 | C21: ='Averaged Data'!C25 -> 9 | D21: ='Averaged Data'!D25 -> 4 | E21: ='Averaged Data'!E25 -> 0.8 | J21: ='Averaged Data'!J25 -> 29.712574 | K21: ='Averaged Data'!K25 -> 2.5452929 | L21: ='Averaged Data'!L25 -> 0.80652782 | M21: ='Averaged Data'!M25 -> 13.4 | N21: ='Averaged Data'!N25 -> 0 | O21: ='Averaged Data'!O25 -> 0.54670944 | P21: ='Averaged Data'!P25 -> 0.057243871 | Q21: ='Averaged Data'!Q25 -> 0.54138455 | R21: ='Averaged Data'!R25 -> 0.09524095 | V21: ='Averaged Data'!V25 -> 325.24356 | W21: ='Averaged Data'!W25 -> 0.034445147 | X21: ='Averaged Data'!X25 -> 0.0036066206 | Y21: ='Averaged Data'!Y25 -> 0.034109655 | Z21: ='Averaged Data'!Z25 -> 0.0060006071
A22: ='Averaged Data'!A27 -> D1 | B22: ='Averaged Data'!B27 -> V1 | C22: ='Averaged Data'!C27 -> 11 | D22: ='Averaged Data'!D27 -> 4 | E22: ='Averaged Data'!E27 -> 1.2 | J22: ='Averaged Data'!J27 -> 29.71055 | K22: ='Averaged Data'!K27 -> 2.5440735 | L22: ='Averaged Data'!L27 -> 1.1985548 | M22: ='Averaged Data'!M27 -> 15.14 | N22: ='Averaged Data'!N27 -> After set to 8deg | O22: ='Averaged Data'!O27 -> 1.73728 | P22: ='Averaged Data'!P27 -> 0.24324865 | Q22: ='Averaged Data'!Q27 -> 1.7160799 | R22: ='Averaged Data'!R27 -> 0.36384264 | V22: ='Averaged Data'!V27 -> 718.26678 | W22: ='Averaged Data'!W27 -> 0.049563757 | X22: ='Averaged Data'!X27 -> 0.0069397662 | Y22: ='Averaged Data'!Y27 -> 0.048958929 | Z22: ='Averaged Data'!Z27 -> 0.010380254
A23: ='Averaged Data'!A26 -> D1 | B23: ='Averaged Data'!B26 -> V1 | C23: ='Averaged Data'!C26 -> 10 | D23: ='Averaged Data'!D26 -> 4 | E23: ='Averaged Data'!E26 -> 1.6 | J23: ='Averaged Data'!J26 -> 29.717892 | K23: ='Averaged Data'!K26 -> 2.5447602 | L23: ='Averaged Data'!L26 -> 1.6057728 | M23: ='Averaged Data'!M26 -> 14.02 | N23: ='Averaged Data'!N26 -> large (or nice) wake pattern | O23: ='Averaged Data'!O26 -> 2.6732155 | P23: ='Averaged Data'!P26 -> 0.70147219 | Q23: ='Averaged Data'!Q26 -> 2.6177715 | R23: ='Averaged Data'!R26 -> 0.88623752 | V23: ='Averaged Data'!V26 -> 1289.2531 | W23: ='Averaged Data'!W26 -> 0.042488945 | X23: ='Averaged Data'!X26 -> 0.011149424 | Y23: ='Averaged Data'!Y26 -> 0.0416077 | Z23: ='Averaged Data'!Z26 -> 0.014086144
A25: ='Averaged Data'!A28 -> D1 | B25: ='Averaged Data'!B28 -> V1 | C25: ='Averaged Data'!C28 -> 12 | D25: ='Averaged Data'!D28 -> 8 | E25: ='Averaged Data'!E28 -> 0.4 | J25: ='Averaged Data'!J28 -> 29.711926 | K25: ='Averaged Data'!K28 -> 2.5410251 | L25: ='Averaged Data'!L28 -> 0.39705455 | M25: ='Averaged Data'!M28 -> 15.4 | N25: ='Averaged Data'!N28 -> 0 | O25: ='Averaged Data'!O28 -> 0.2216323 | P25: ='Averaged Data'!P28 -> 0.043571464 | Q25: ='Averaged Data'!Q28 -> 0.21341142 | R25: ='Averaged Data'!R28 -> 0.073992684 | V25: ='Averaged Data'!V28 -> 78.826159 | W25: ='Averaged Data'!W28 -> 0.057615969 | X25: ='Averaged Data'!X28 -> 0.011326923 | Y25: ='Averaged Data'!Y28 -> 0.055478851 | Z25: ='Averaged Data'!Z28 -> 0.019235284
A26: ='Averaged Data'!A29 -> D1 | B26: ='Averaged Data'!B29 -> V1 | C26: ='Averaged Data'!C29 -> 13 | D26: ='Averaged Data'!D29 -> 8 | E26: ='Averaged Data'!E29 -> 0.8 | J26: ='Averaged Data'!J29 -> 29.710793 | K26: ='Averaged Data'!K29 -> 2.537367 | L26: ='Averaged Data'!L29 -> 0.80848332 | M26: ='Averaged Data'!M29 -> 15.53 | N26: ='Averaged Data'!N29 -> photographed | O26: ='Averaged Data'!O29 -> 0.60233237 | P26: ='Averaged Data'!P29 -> 0.21815929 | Q26: ='Averaged Data'!Q29 -> 0.56610861 | R26: ='Averaged Data'!R29 -> 0.29986464 | V26: ='Averaged Data'!V29 -> 326.82264 | W26: ='Averaged Data'!W29 -> 0.037766284 | X26: ='Averaged Data'!X29 -> 0.013678603 | Y26: ='Averaged Data'!Y29 -> 0.035495051 | Z26: ='Averaged Data'!Z29 -> 0.018801535
A27: ='Averaged Data'!A30 -> D1 | B27: ='Averaged Data'!B30 -> V1 | C27: ='Averaged Data'!C30 -> 14 | D27: ='Averaged Data'!D30 -> 8 | E27: ='Averaged Data'!E30 -> 1.2 | J27: ='Averaged Data'!J30 -> 29.71144 | K27: ='Averaged Data'!K30 -> 2.5420703 | L27: ='Averaged Data'!L30 -> 1.1940426 | M27: ='Averaged Data'!M30 -> 14.29 | N27: ='Averaged Data'!N30 -> photo again. Strange time. Probably 16.29 | O27: ='Averaged Data'!O30 -> 1.8254385 | P27: ='Averaged Data'!P30 -> 0.97098647 | Q27: ='Averaged Data'!Q30 -> 1.6725382 | R27: ='Averaged Data'!R30 -> 1.2155888 | V27: ='Averaged Data'!V30 -> 712.86882 | W27: ='Averaged Data'!W30 -> 0.052473225 | X27: ='Averaged Data'!X30 -> 0.027911536 | Y27: ='Averaged Data'!Y30 -> 0.048078024 | Z27: ='Averaged Data'!Z30 -> 0.034942764
A28: ='Averaged Data'!A31 -> D2 | B28: ='Averaged Data'!B31 -> V1 | C28: ='Averaged Data'!C31 -> 1 | D28: ='Averaged Data'!D31 -> 8 | E28: ='Averaged Data'!E31 -> 1.2 | J28: ='Averaged Data'!J31 -> 29.722714 | K28: ='Averaged Data'!K31 -> 2.5286184 | L28: ='Averaged Data'!L31 -> 1.1942638 | M28: ='Averaged Data'!M31 -> 0 | N28: ='Averaged Data'!N31 -> Ian skimmed tank before tests. Previous test with model rotated bow to port, following tests with bow rotated to starboard. Data recorded for only 5 sec, not 10 sec. After set to 16 degs | O28: ='Averaged Data'!O31 -> 1.3806132 | P28: ='Averaged Data'!P31 -> 0.83014633 | Q28: ='Averaged Data'!Q31 -> 1.2516432 | R28: ='Averaged Data'!R31 -> 1.0142116 | V28: ='Averaged Data'!V31 -> 713.13304 | W28: ='Averaged Data'!W31 -> 0.039671776 | X28: ='Averaged Data'!X31 -> 0.023854168 | Y28: ='Averaged Data'!Y31 -> 0.035965835 | Z28: ='Averaged Data'!Z31 -> 0.029143265
D29: 12 | E29: -10 | L29: -10 | O29: 0 | P29: 0 | W29: 0 | X29: 0 | Y29: 0 | Z29: 0
A30: ='Averaged Data'!A32 -> D2 | B30: ='Averaged Data'!B32 -> V1 | C30: ='Averaged Data'!C32 -> 2 | D30: ='Averaged Data'!D32 -> 16 | E30: ='Averaged Data'!E32 -> 0.4 | J30: ='Averaged Data'!J32 -> 29.721966 | K30: ='Averaged Data'!K32 -> 2.5239516 | L30: ='Averaged Data'!L32 -> 0.39916287 | M30: ='Averaged Data'!M32 -> 0 | N30: ='Averaged Data'!N32 -> Data recorded for only 5 sec, not 10 sec. Video + photo | O30: ='Averaged Data'!O32 -> 0.11927838 | P30: ='Averaged Data'!P32 -> 0.29648215 | Q30: ='Averaged Data'!Q32 -> 0.032936177 | R30: ='Averaged Data'!R32 -> 0.31787451 | V30: ='Averaged Data'!V32 -> 79.665499 | W30: ='Averaged Data'!W32 -> 0.030681148 | X30: ='Averaged Data'!X32 -> 0.076262045 | Y30: ='Averaged Data'!Y32 -> 0.0084719443 | Z30: ='Averaged Data'!Z32 -> 0.081764653
A31: ='Averaged Data'!A33 -> D2 | B31: ='Averaged Data'!B33 -> V1 | C31: ='Averaged Data'!C33 -> 3 | D31: ='Averaged Data'!D33 -> 16 | E31: ='Averaged Data'!E33 -> 0.8 | J31: ='Averaged Data'!J33 -> 29.718081 | K31: ='Averaged Data'!K33 -> 2.5276122 | L31: ='Averaged Data'!L33 -> 0.80877014 | M31: ='Averaged Data'!M33 -> 10.35 | N31: ='Averaged Data'!N33 -> Data recorded for 10 sec. Ran again to check recording was working properly. Seemed ok | O31: ='Averaged Data'!O33 -> 0.48797141 | P31: ='Averaged Data'!P33 -> 0.7436845 | Q31: ='Averaged Data'!Q33 -> 0.26408099 | R31: ='Averaged Data'!R33 -> 0.84937858 | V31: ='Averaged Data'!V33 -> 327.05457 | W31: ='Averaged Data'!W33 -> 0.030574145 | X31: ='Averaged Data'!X33 -> 0.046596005 | Y31: ='Averaged Data'!Y33 -> 0.016546155 | Z31: ='Averaged Data'!Z33 -> 0.053218331
A32: ='Averaged Data'!A34 -> D2 | B32: ='Averaged Data'!B34 -> V1 | C32: ='Averaged Data'!C34 -> 4 | D32: ='Averaged Data'!D34 -> 16 | E32: ='Averaged Data'!E34 -> 1.2 | J32: ='Averaged Data'!J34 -> 29.717029 | K32: ='Averaged Data'!K34 -> 2.5282219 | L32: ='Averaged Data'!L34 -> 1.1962005 | M32: ='Averaged Data'!M34 -> 11.05 | N32: ='Averaged Data'!N34 -> 0 | O32: ='Averaged Data'!O34 -> 2.0054195 | P32: ='Averaged Data'!P34 -> 2.088767 | Q32: ='Averaged Data'!Q34 -> 1.3519908 | R32: ='Averaged Data'!R34 -> 2.5606203 | V32: ='Averaged Data'!V34 -> 715.44785 | W32: ='Averaged Data'!W34 -> 0.057439075 | X32: ='Averaged Data'!X34 -> 0.059826307 | Y32: ='Averaged Data'!Y34 -> 0.038723617 | Z32: ='Averaged Data'!Z34 -> 0.073341092
A33: ='Averaged Data'!A35 -> D2 | B33: ='Averaged Data'!B35 -> V1 | C33: ='Averaged Data'!C35 -> 5 | D33: ='Averaged Data'!D35 -> 24 | E33: ='Averaged Data'!E35 -> 0.4 | J33: ='Averaged Data'!J35 -> 29.714518 | K33: ='Averaged Data'!K35 -> 2.5283961 | L33: ='Averaged Data'!L35 -> 0.40077542 | M33: ='Averaged Data'!M35 -> 11.36 | N33: ='Averaged Data'!N35 -> 0 | O33: ='Averaged Data'!O35 -> 0.30683526 | P33: ='Averaged Data'!P35 -> 0.56107662 | Q33: ='Averaged Data'!Q35 -> 0.052097542 | R33: ='Averaged Data'!R35 -> 0.63737014 | V33: ='Averaged Data'!V35 -> 80.310467 | W33: ='Averaged Data'!W35 -> 0.078291263 | X33: ='Averaged Data'!X35 -> 0.1431628 | Y33: ='Averaged Data'!Y35 -> 0.013293069 | Z33: ='Averaged Data'!Z35 -> 0.16262966
A34: ='Averaged Data'!A36 -> D2 | B34: ='Averaged Data'!B36 -> V1 | C34: ='Averaged Data'!C36 -> 6 | D34: ='Averaged Data'!D36 -> 24 | E34: ='Averaged Data'!E36 -> 0.8 | J34: ='Averaged Data'!J36 -> 29.712007 | K34: ='Averaged Data'!K36 -> 2.5250864 | L34: ='Averaged Data'!L36 -> 0.80715357 | M34: ='Averaged Data'!M36 -> 12.04 | N34: ='Averaged Data'!N36 -> 0 | O34: ='Averaged Data'!O36 -> 1.0403196 | P34: ='Averaged Data'!P36 -> 1.2743563 | Q34: ='Averaged Data'!Q36 -> 0.43205185 | R34: ='Averaged Data'!R36 -> 1.5873185 | V34: ='Averaged Data'!V36 -> 325.74845 | W34: ='Averaged Data'!W36 -> 0.065443211 | X34: ='Averaged Data'!X36 -> 0.080165718 | Y34: ='Averaged Data'!Y36 -> 0.027179014 | Z34: ='Averaged Data'!Z36 -> 0.099853179
A35: ='Averaged Data'!A37 -> D2 | B35: ='Averaged Data'!B37 -> V1 | C35: ='Averaged Data'!C37 -> 7 | D35: ='Averaged Data'!D37 -> 24 | E35: ='Averaged Data'!E37 -> 1.2 | J35: ='Averaged Data'!J37 -> 29.715166 | K35: ='Averaged Data'!K37 -> 2.5304864 | L35: ='Averaged Data'!L37 -> 1.196084 | M35: ='Averaged Data'!M37 -> 12.3 | N35: ='Averaged Data'!N37 -> waterline well below on leeward side. | O35: ='Averaged Data'!O37 -> 2.8111068 | P35: ='Averaged Data'!P37 -> 3.2395256 | Q35: ='Averaged Data'!Q37 -> 1.2504401 | R35: ='Averaged Data'!R37 -> 4.102834 | V35: ='Averaged Data'!V37 -> 715.30843 | W35: ='Averaged Data'!W37 -> 0.080531203 | X35: ='Averaged Data'!X37 -> 0.092804331 | Y35: ='Averaged Data'!Y37 -> 0.035821992 | Z35: ='Averaged Data'!Z37 -> 0.11753597
A37: ='Averaged Data'!A39 -> D2 | B37: ='Averaged Data'!B39 -> V2 | C37: ='Averaged Data'!C39 -> 1 | D37: ='Averaged Data'!D39 -> 0 | E37: ='Averaged Data'!E39 -> 0.4 | J37: ='Averaged Data'!J39 -> 25.708994 | K37: ='Averaged Data'!K39 -> 2.5307477 | L37: ='Averaged Data'!L39 -> 0.39910058 | M37: ='Averaged Data'!M39 -> 13.58 | N37: ='Averaged Data'!N39 -> 0 | O37: ='Averaged Data'!O39 -> 0.027794197 | P37: ='Averaged Data'!P39 -> 0.018148468 | Q37: ='Averaged Data'!Q39 -> 0.027794197 | R37: ='Averaged Data'!R39 -> 0.018148468 | V37: ='Averaged Data'!V39 -> 79.640636 | W37: ='Averaged Data'!W39 -> 0.0071515402 | X37: ='Averaged Data'!X39 -> 0.0046696618 | Y37: ='Averaged Data'!Y39 -> 0.0071515402 | Z37: ='Averaged Data'!Z39 -> 0.0046696618
A38: ='Averaged Data'!A40 -> D2 | B38: ='Averaged Data'!B40 -> V2 | C38: ='Averaged Data'!C40 -> 2 | D38: ='Averaged Data'!D40 -> 0 | E38: ='Averaged Data'!E40 -> 0.8 | J38: ='Averaged Data'!J40 -> 25.711423 | K38: ='Averaged Data'!K40 -> 2.5282219 | L38: ='Averaged Data'!L40 -> 0.80760298 | M38: ='Averaged Data'!M40 -> 14.1 | N38: ='Averaged Data'!N40 -> 0 | O38: ='Averaged Data'!O40 -> 0.43268671 | P38: ='Averaged Data'!P40 -> 0.045955954 | Q38: ='Averaged Data'!Q40 -> 0.43268671 | R38: ='Averaged Data'!R40 -> 0.045955954 | V38: ='Averaged Data'!V40 -> 326.11128 | W38: ='Averaged Data'!W40 -> 0.027188666 | X38: ='Averaged Data'!X40 -> 0.002887727 | Y38: ='Averaged Data'!Y40 -> 0.027188666 | Z38: ='Averaged Data'!Z40 -> 0.002887727
A39: ='Averaged Data'!A41 -> D2 | B39: ='Averaged Data'!B41 -> V2 | C39: ='Averaged Data'!C41 -> 3 | D39: ='Averaged Data'!D41 -> 0 | E39: ='Averaged Data'!E41 -> 1.2 | J39: ='Averaged Data'!J41 -> 25.706726 | K39: ='Averaged Data'!K41 -> 2.5298767 | L39: ='Averaged Data'!L41 -> 1.1963631 | M39: ='Averaged Data'!M41 -> 14.27 | N39: ='Averaged Data'!N41 -> 0 | O39: ='Averaged Data'!O41 -> 0.82467747 | P39: ='Averaged Data'!P41 -> 0.11392364 | Q39: ='Averaged Data'!Q41 -> 0.82467747 | R39: ='Averaged Data'!R41 -> 0.11392364 | V39: ='Averaged Data'!V41 -> 715.64233 | W39: ='Averaged Data'!W41 -> 0.023613931 | X39: ='Averaged Data'!X41 -> 0.0032621056 | Y39: ='Averaged Data'!Y41 -> 0.023613931 | Z39: ='Averaged Data'!Z41 -> 0.0032621056
A40: ='Averaged Data'!A42 -> D2 | B40: ='Averaged Data'!B42 -> V2 | C40: ='Averaged Data'!C42 -> 4 | D40: ='Averaged Data'!D42 -> 0 | E40: ='Averaged Data'!E42 -> 1.6 | J40: ='Averaged Data'!J42 -> 25.707095 | K40: ='Averaged Data'!K42 -> 2.5265951 | L40: ='Averaged Data'!L42 -> 1.6066749 | M40: ='Averaged Data'!M42 -> 14.56 | N40: ='Averaged Data'!N42 -> 0 | O40: ='Averaged Data'!O42 -> 1.2398563 | P40: ='Averaged Data'!P42 -> 0.17931918 | Q40: ='Averaged Data'!Q42 -> 1.2398563 | R40: ='Averaged Data'!R42 -> 0.17931918 | V40: ='Averaged Data'!V42 -> 1290.7021 | W40: ='Averaged Data'!W42 -> 0.019684552 | X40: ='Averaged Data'!X42 -> 0.002846957 | Y40: ='Averaged Data'!Y42 -> 0.019684552 | Z40: ='Averaged Data'!Z42 -> 0.002846957
D41: 4 | E41: -10 | L41: -10 | O41: 0 | P41: 0 | W41: 0 | X41: 0 | Y41: 0 | Z41: 0
A42: ='Averaged Data'!A43 -> D2 | B42: ='Averaged Data'!B43 -> V2 | C42: ='Averaged Data'!C43 -> 5 | D42: ='Averaged Data'!D43 -> 8 | E42: ='Averaged Data'!E43 -> 0.4 | J42: ='Averaged Data'!J43 -> 25.702353 | K42: ='Averaged Data'!K43 -> 2.5248251 | L42: ='Averaged Data'!L43 -> 0.40032756 | M42: ='Averaged Data'!M43 -> 15.33 | N42: ='Averaged Data'!N43 -> 0 | O42: ='Averaged Data'!O43 -> 0.06273998 | P42: ='Averaged Data'!P43 -> 0.20249228 | Q42: ='Averaged Data'!Q43 -> 0.03394792 | R42: ='Averaged Data'!R43 -> 0.20925336 | V42: ='Averaged Data'!V43 -> 80.131078 | W42: ='Averaged Data'!W43 -> 0.016044403 | X42: ='Averaged Data'!X43 -> 0.051783055 | Y42: ='Averaged Data'!Y43 -> 0.0086814519 | Z42: ='Averaged Data'!Z43 -> 0.053512055
A43: ='Averaged Data'!A44 -> D2 | B43: ='Averaged Data'!B44 -> V2 | C43: ='Averaged Data'!C44 -> 6 | D43: ='Averaged Data'!D44 -> 8 | E43: ='Averaged Data'!E44 -> 0.8 | J43: ='Averaged Data'!J44 -> 25.702596 | K43: ='Averaged Data'!K44 -> 2.5228219 | L43: ='Averaged Data'!L44 -> 0.80967196 | M43: ='Averaged Data'!M44 -> 15.47 | N43: ='Averaged Data'!N44 -> 0 | O43: ='Averaged Data'!O44 -> 0.53100439 | P43: ='Averaged Data'!P44 -> 0.80362217 | Q43: ='Averaged Data'!Q44 -> 0.4139941 | R43: ='Averaged Data'!R44 -> 0.86970291 | V43: ='Averaged Data'!V44 -> 327.78434 | W43: ='Averaged Data'!W44 -> 0.033196331 | X43: ='Averaged Data'!X44 -> 0.050239335 | Y43: ='Averaged Data'!Y44 -> 0.025881302 | Z43: ='Averaged Data'!Z44 -> 0.054370446
A44: ='Averaged Data'!A45 -> D2 | B44: ='Averaged Data'!B45 -> V2 | C44: ='Averaged Data'!C45 -> 7 | D44: ='Averaged Data'!D45 -> 8 | E44: ='Averaged Data'!E45 -> 1.2 | J44: ='Averaged Data'!J45 -> 25.702596 | K44: ='Averaged Data'!K45 -> 2.523867 | L44: ='Averaged Data'!L45 -> 1.1992925 | M44: ='Averaged Data'!M45 -> 0 | N44: ='Averaged Data'!N45 -> 0 | O44: ='Averaged Data'!O45 -> 0.95143993 | P44: ='Averaged Data'!P45 -> 2.0535953 | Q44: ='Averaged Data'!Q45 -> 0.65637535 | R44: ='Averaged Data'!R45 -> 2.1660247 | V44: ='Averaged Data'!V45 -> 719.15126 | W44: ='Averaged Data'!W45 -> 0.027110736 | X44: ='Averaged Data'!X45 -> 0.058516022 | Y44: ='Averaged Data'!Y45 -> 0.01870304 | Z44: ='Averaged Data'!Z45 -> 0.061719634
A45: ='Averaged Data'!A46 -> D2 | B45: ='Averaged Data'!B46 -> V2 | C45: ='Averaged Data'!C46 -> 8 | D45: ='Averaged Data'!D46 -> 8 | E45: ='Averaged Data'!E46 -> 1.6 | J45: ='Averaged Data'!J46 -> 25.702301 | K45: ='Averaged Data'!K46 -> 2.5269108 | L45: ='Averaged Data'!L46 -> 1.6056374 | M45: ='Averaged Data'!M46 -> 0 | N45: ='Averaged Data'!N46 -> Final run of the day | O45: ='Averaged Data'!O46 -> 1.6827219 | P45: ='Averaged Data'!P46 -> 3.547652 | Q45: ='Averaged Data'!Q46 -> 1.172608 | R45: ='Averaged Data'!R46 -> 3.7473161 | V45: ='Averaged Data'!V46 -> 1289.0357 | W45: ='Averaged Data'!W46 -> 0.026750234 | X45: ='Averaged Data'!X46 -> 0.056397032 | Y45: ='Averaged Data'!Y46 -> 0.018640953 | Z45: ='Averaged Data'!Z46 -> 0.059571092
...

Sheet Results vs yaw
A1: Edited 23/10/13, 24/10/13 | P1: U | Q1: V1 | R1: V2
A2: Page copied from "Results vs speed" and then rows manipulated to group same angles together for each model | M2: 0.4 | P2: =P$1&", "&$M2&" m/s" -> U, 0.4 m/s | Q2: =Q$1&", "&$M2&" m/s" -> V1, 0.4 m/s | R2: =R$1&", "&$M2&" m/s" -> V2, 0.4 m/s | AD2: All these figures need to be changed to show results vs yaw.
M3: 0.8 | P3: =P$1&", "&$M3&" m/s" -> U, 0.8 m/s | Q3: =Q$1&", "&$M3&" m/s" -> V1, 0.8 m/s | R3: =R$1&", "&$M3&" m/s" -> V2, 0.8 m/s | AD3: RGJF 24/10/13
A4: Note dummy yellow rows inserted to keep legend ordered | M4: 1.2 | P4: =P$1&", "&$M4&" m/s" -> U, 1.2 m/s | Q4: =Q$1&", "&$M4&" m/s" -> V1, 1.2 m/s | R4: =R$1&", "&$M4&" m/s" -> V2, 1.2 m/s | AD4: Done, RGJF 25/10/13
M5: 1.6 | P5: =P$1&", "&$M5&" m/s" -> U, 1.6 m/s | Q5: =Q$1&", "&$M5&" m/s" -> V1, 1.6 m/s | R5: =R$1&", "&$M5&" m/s" -> V2, 1.6 m/s | AD5: Need to add Florin's CFD sideforce predictions
A10: ='Averaged Data'!A10 -> 0 | B10: ='Averaged Data'!B10 -> 0 | C10: ='Averaged Data'!C10 -> 0 | D10: ='Averaged Data'!D10 -> 0 | E10: ='Averaged Data'!E10 -> 0 | J10: ='Averaged Data'!J10 -> Measured | K10: ='Averaged Data'!K10 -> Measured | L10: ='Averaged Data'!L10 -> Measured | M10: ='Averaged Data'!M10 -> Time | N10: ='Averaged Data'!N10 -> Comment | O10: ='Averaged Data'!O10 -> Calc | P10: ='Averaged Data'!P10 -> Calc | Q10: ='Averaged Data'!Q10 -> Calc | ... Z10: ='Averaged Data'!Z10 -> coefts
A11: ='Averaged Data'!A11 -> 0 | B11: ='Averaged Data'!B11 -> 0 | C11: ='Averaged Data'!C11 -> 0 | D11: ='Averaged Data'!D11 -> 0 | E11: ='Averaged Data'!E11 -> 0 | J11: ='Averaged Data'!J11 -> 0 | K11: ='Averaged Data'!K11 -> 0 | L11: ='Averaged Data'!L11 -> 0 | M11: ='Averaged Data'!M11 -> 0 | N11: ='Averaged Data'!N11 -> 0 | O11: ='Averaged Data'!O11 -> 0 | P11: ='Averaged Data'!P11 -> 0 | Q11: ='Averaged Data'!Q11 -> 0 | ... Z11: ='Averaged Data'!Z11 -> 0
A12: ='Averaged Data'!A12 -> Day | B12: ='Averaged Data'!B12 -> Model | C12: ='Averaged Data'!C12 -> Test | D12: ='Averaged Data'!D12 -> Yaw | E12: ='Averaged Data'!E12 -> Speed | J12: ='Averaged Data'!J12 -> Heave | K12: ='Averaged Data'!K12 -> Pitch | L12: ='Averaged Data'!L12 -> Velocity | M12: ='Averaged Data'!M12 -> 0 | N12: ='Averaged Data'!N12 -> 0 | O12: ='Averaged Data'!O12 -> Total Drag | P12: ='Averaged Data'!P12 -> Total Lift | Q12: ='Averaged Data'!Q12 -> Resistance | ... Z12: ='Averaged Data'!Z12 -> CS
A13: ='Averaged Data'!A13 -> 0 | B13: ='Averaged Data'!B13 -> shape | C13: ='Averaged Data'!C13 -> number | D13: ='Averaged Data'!D13 -> deg | E13: ='Averaged Data'!E13 -> m/s | J13: ='Averaged Data'!J13 -> mm | K13: ='Averaged Data'!K13 -> deg | L13: ='Averaged Data'!L13 -> m/s | M13: ='Averaged Data'!M13 -> 0 | N13: ='Averaged Data'!N13 -> 0 | O13: ='Averaged Data'!O13 -> N | P13: ='Averaged Data'!P13 -> N | Q13: ='Averaged Data'!Q13 -> N | ... Z13: ='Averaged Data'!Z13 -> 0
A15: ='Averaged Data'!A17 -> D1 | B15: ='Averaged Data'!B17 -> V1 | C15: ='Averaged Data'!C17 -> 2 | D15: ='Averaged Data'!D17 -> 0 | E15: ='Averaged Data'!E17 -> 0.4 | J15: ='Averaged Data'!J17 -> 29.737275 | K15: ='Averaged Data'!K17 -> 2.5435509 | L15: ='Averaged Data'!L17 -> 0.39915733 | M15: ='Averaged Data'!M17 -> 0 | N15: ='Averaged Data'!N17 -> 0 | O15: ='Averaged Data'!O17 -> 0.008227737 | P15: ='Averaged Data'!P17 -> 0.051265825 | Q15: ='Averaged Data'!Q17 -> 0.008227737 | ... Z15: ='Averaged Data'!Z17 -> 0.013187118
A16: ='Averaged Data'!A18 -> D1 | B16: ='Averaged Data'!B18 -> V1 | C16: ='Averaged Data'!C18 -> 3 | D16: ='Averaged Data'!D18 -> 0 | E16: ='Averaged Data'!E18 -> 0.4 | J16: ='Averaged Data'!J18 -> 29.737275 | K16: ='Averaged Data'!K18 -> 2.5444219 | L16: ='Averaged Data'!L18 -> 0.39916652 | M16: ='Averaged Data'!M18 -> 11.04 | N16: ='Averaged Data'!N18 -> good run | O16: ='Averaged Data'!O18 -> 0.09930452 | P16: ='Averaged Data'!P18 -> -0.027159804 | Q16: ='Averaged Data'!Q18 -> 0.09930452 | ... Z16: ='Averaged Data'!Z18 -> -0.0069860002
A17: ='Averaged Data'!A24 -> D1 | B17: ='Averaged Data'!B24 -> V1 | C17: ='Averaged Data'!C24 -> 8 | D17: ='Averaged Data'!D24 -> 4 | E17: ='Averaged Data'!E24 -> 0.4 | J17: ='Averaged Data'!J24 -> 29.71549 | K17: ='Averaged Data'!K24 -> 2.5423316 | L17: ='Averaged Data'!L24 -> 0.40036896 | M17: ='Averaged Data'!M24 -> 13.25 | N17: ='Averaged Data'!N24 -> 0 | O17: ='Averaged Data'!O24 -> 0.059672465 | P17: ='Averaged Data'!P24 -> 0.03548981 | Q17: ='Averaged Data'!Q24 -> 0.057051462 | ... Z17: ='Averaged Data'!Z24 -> 0.010116037
A18: ='Averaged Data'!A32 -> D2 | B18: ='Averaged Data'!B32 -> V1 | C18: ='Averaged Data'!C32 -> 2 | D18: ='Averaged Data'!D32 -> 16 | E18: ='Averaged Data'!E32 -> 0.4 | J18: ='Averaged Data'!J32 -> 29.721966 | K18: ='Averaged Data'!K32 -> 2.5239516 | L18: ='Averaged Data'!L32 -> 0.39916287 | M18: ='Averaged Data'!M32 -> 0 | N18: ='Averaged Data'!N32 -> Data recorded for only 5 sec, not 10 sec. Video + photo | O18: ='Averaged Data'!O32 -> 0.11927838 | P18: ='Averaged Data'!P32 -> 0.29648215 | Q18: ='Averaged Data'!Q32 -> 0.032936177 | ... Z18: ='Averaged Data'!Z32 -> 0.081764653
A19: ='Averaged Data'!A35 -> D2 | B19: ='Averaged Data'!B35 -> V1 | C19: ='Averaged Data'!C35 -> 5 | D19: ='Averaged Data'!D35 -> 24 | E19: ='Averaged Data'!E35 -> 0.4 | J19: ='Averaged Data'!J35 -> 29.714518 | K19: ='Averaged Data'!K35 -> 2.5283961 | L19: ='Averaged Data'!L35 -> 0.40077542 | M19: ='Averaged Data'!M35 -> 11.36 | N19: ='Averaged Data'!N35 -> 0 | O19: ='Averaged Data'!O35 -> 0.30683526 | P19: ='Averaged Data'!P35 -> 0.56107662 | Q19: ='Averaged Data'!Q35 -> 0.052097542 | ... Z19: ='Averaged Data'!Z35 -> 0.16262966
A20: ='Averaged Data'!A19 -> D1 | B20: ='Averaged Data'!B19 -> V1 | C20: ='Averaged Data'!C19 -> 4 | D20: ='Averaged Data'!D19 -> 0 | E20: ='Averaged Data'!E19 -> 0.8 | J20: ='Averaged Data'!J19 -> 29.727557 | K20: ='Averaged Data'!K19 -> 2.5452929 | L20: ='Averaged Data'!L19 -> 0.80495266 | M20: ='Averaged Data'!M19 -> 11.27 | N20: ='Averaged Data'!N19 -> 0 | O20: ='Averaged Data'!O19 -> 0.51653595 | P20: ='Averaged Data'!P19 -> -0.034391373 | Q20: ='Averaged Data'!Q19 -> 0.51653595 | ... Z20: ='Averaged Data'!Z19 -> -0.0021752992
A21: ='Averaged Data'!A25 -> D1 | B21: ='Averaged Data'!B25 -> V1 | C21: ='Averaged Data'!C25 -> 9 | D21: ='Averaged Data'!D25 -> 4 | E21: ='Averaged Data'!E25 -> 0.8 | J21: ='Averaged Data'!J25 -> 29.712574 | K21: ='Averaged Data'!K25 -> 2.5452929 | L21: ='Averaged Data'!L25 -> 0.80652782 | M21: ='Averaged Data'!M25 -> 13.4 | N21: ='Averaged Data'!N25 -> 0 | O21: ='Averaged Data'!O25 -> 0.54670944 | P21: ='Averaged Data'!P25 -> 0.057243871 | Q21: ='Averaged Data'!Q25 -> 0.54138455 | ... Z21: ='Averaged Data'!Z25 -> 0.0060006071
A22: ='Averaged Data'!A29 -> D1 | B22: ='Averaged Data'!B29 -> V1 | C22: ='Averaged Data'!C29 -> 13 | D22: ='Averaged Data'!D29 -> 8 | E22: ='Averaged Data'!E29 -> 0.8 | J22: ='Averaged Data'!J29 -> 29.710793 | K22: ='Averaged Data'!K29 -> 2.537367 | L22: ='Averaged Data'!L29 -> 0.80848332 | M22: ='Averaged Data'!M29 -> 15.53 | N22: ='Averaged Data'!N29 -> photographed | O22: ='Averaged Data'!O29 -> 0.60233237 | P22: ='Averaged Data'!P29 -> 0.21815929 | Q22: ='Averaged Data'!Q29 -> 0.56610861 | ... Z22: ='Averaged Data'!Z29 -> 0.018801535
A23: ='Averaged Data'!A33 -> D2 | B23: ='Averaged Data'!B33 -> V1 | C23: ='Averaged Data'!C33 -> 3 | D23: ='Averaged Data'!D33 -> 16 | E23: ='Averaged Data'!E33 -> 0.8 | J23: ='Averaged Data'!J33 -> 29.718081 | K23: ='Averaged Data'!K33 -> 2.5276122 | L23: ='Averaged Data'!L33 -> 0.80877014 | M23: ='Averaged Data'!M33 -> 10.35 | N23: ='Averaged Data'!N33 -> Data recorded for 10 sec. Ran again to check recording was working properly. Seemed ok | O23: ='Averaged Data'!O33 -> 0.48797141 | P23: ='Averaged Data'!P33 -> 0.7436845 | Q23: ='Averaged Data'!Q33 -> 0.26408099 | ... Z23: ='Averaged Data'!Z33 -> 0.053218331
A24: ='Averaged Data'!A36 -> D2 | B24: ='Averaged Data'!B36 -> V1 | C24: ='Averaged Data'!C36 -> 6 | D24: ='Averaged Data'!D36 -> 24 | E24: ='Averaged Data'!E36 -> 0.8 | J24: ='Averaged Data'!J36 -> 29.712007 | K24: ='Averaged Data'!K36 -> 2.5250864 | L24: ='Averaged Data'!L36 -> 0.80715357 | M24: ='Averaged Data'!M36 -> 12.04 | N24: ='Averaged Data'!N36 -> 0 | O24: ='Averaged Data'!O36 -> 1.0403196 | P24: ='Averaged Data'!P36 -> 1.2743563 | Q24: ='Averaged Data'!Q36 -> 0.43205185 | ... Z24: ='Averaged Data'!Z36 -> 0.099853179
A25: ='Averaged Data'!A20 -> D1 | B25: ='Averaged Data'!B20 -> V1 | C25: ='Averaged Data'!C20 -> 5 | D25: ='Averaged Data'!D20 -> 0 | E25: ='Averaged Data'!E20 -> 1.2 | J25: ='Averaged Data'!J20 -> 29.725532 | K25: ='Averaged Data'!K20 -> 2.5442477 | L25: ='Averaged Data'!L20 -> 1.1953708 | M25: ='Averaged Data'!M20 -> 11.5 | N25: ='Averaged Data'!N20 -> Originally didn't change file name before run. Recovered | O25: ='Averaged Data'!O20 -> 1.6150736 | P25: ='Averaged Data'!P20 -> -0.1898065 | Q25: ='Averaged Data'!Q20 -> 1.6150736 | ... Z25: ='Averaged Data'!Z20 -> -0.0054439734
A26: ='Averaged Data'!A27 -> D1 | B26: ='Averaged Data'!B27 -> V1 | C26: ='Averaged Data'!C27 -> 11 | D26: ='Averaged Data'!D27 -> 4 | E26: ='Averaged Data'!E27 -> 1.2 | J26: ='Averaged Data'!J27 -> 29.71055 | K26: ='Averaged Data'!K27 -> 2.5440735 | L26: ='Averaged Data'!L27 -> 1.1985548 | M26: ='Averaged Data'!M27 -> 15.14 | N26: ='Averaged Data'!N27 -> After set to 8deg | O26: ='Averaged Data'!O27 -> 1.73728 | P26: ='Averaged Data'!P27 -> 0.24324865 | Q26: ='Averaged Data'!Q27 -> 1.7160799 | ... Z26: ='Averaged Data'!Z27 -> 0.010380254
A27: ='Averaged Data'!A30 -> D1 | B27: ='Averaged Data'!B30 -> V1 | C27: ='Averaged Data'!C30 -> 14 | D27: ='Averaged Data'!D30 -> 8 | E27: ='Averaged Data'!E30 -> 1.2 | J27: ='Averaged Data'!J30 -> 29.71144 | K27: ='Averaged Data'!K30 -> 2.5420703 | L27: ='Averaged Data'!L30 -> 1.1940426 | M27: ='Averaged Data'!M30 -> 14.29 | N27: ='Averaged Data'!N30 -> photo again. Strange time. Probably 16.29 | O27: ='Averaged Data'!O30 -> 1.8254385 | P27: ='Averaged Data'!P30 -> 0.97098647 | Q27: ='Averaged Data'!Q30 -> 1.6725382 | ... Z27: ='Averaged Data'!Z30 -> 0.034942764
A28: ='Averaged Data'!A34 -> D2 | B28: ='Averaged Data'!B34 -> V1 | C28: ='Averaged Data'!C34 -> 4 | D28: ='Averaged Data'!D34 -> 16 | E28: ='Averaged Data'!E34 -> 1.2 | J28: ='Averaged Data'!J34 -> 29.717029 | K28: ='Averaged Data'!K34 -> 2.5282219 | L28: ='Averaged Data'!L34 -> 1.1962005 | M28: ='Averaged Data'!M34 -> 11.05 | N28: ='Averaged Data'!N34 -> 0 | O28: ='Averaged Data'!O34 -> 2.0054195 | P28: ='Averaged Data'!P34 -> 2.088767 | Q28: ='Averaged Data'!Q34 -> 1.3519908 | ... Z28: ='Averaged Data'!Z34 -> 0.073341092
A29: ='Averaged Data'!A37 -> D2 | B29: ='Averaged Data'!B37 -> V1 | C29: ='Averaged Data'!C37 -> 7 | D29: ='Averaged Data'!D37 -> 24 | E29: ='Averaged Data'!E37 -> 1.2 | J29: ='Averaged Data'!J37 -> 29.715166 | K29: ='Averaged Data'!K37 -> 2.5304864 | L29: ='Averaged Data'!L37 -> 1.196084 | M29: ='Averaged Data'!M37 -> 12.3 | N29: ='Averaged Data'!N37 -> waterline well below on leeward side. | O29: ='Averaged Data'!O37 -> 2.8111068 | P29: ='Averaged Data'!P37 -> 3.2395256 | Q29: ='Averaged Data'!Q37 -> 1.2504401 | ... Z29: ='Averaged Data'!Z37 -> 0.11753597
A30: ='Averaged Data'!A22 -> D1 | B30: ='Averaged Data'!B22 -> V1 | C30: ='Averaged Data'!C22 -> 6 | D30: ='Averaged Data'!D22 -> 0 | E30: ='Averaged Data'!E22 -> 1.6 | J30: ='Averaged Data'!J22 -> 29.712471 | K30: ='Averaged Data'!K22 -> 2.5437002 | L30: ='Averaged Data'!L22 -> 1.605672 | M30: ='Averaged Data'!M22 -> ~14.35 | N30: ='Averaged Data'!N22 -> re-run of test 6 to confirm bow over the top. From now on only test to 1.2m/s.This test done after test 10 | O30: ='Averaged Data'!O22 -> 2.4866431 | P30: ='Averaged Data'!P22 -> -0.33239352 | Q30: ='Averaged Data'!Q22 -> 2.4866431 | ... Z30: ='Averaged Data'!Z22 -> -0.0052838326
A31: ='Averaged Data'!A26 -> D1 | B31: ='Averaged Data'!B26 -> V1 | C31: ='Averaged Data'!C26 -> 10 | D31: ='Averaged Data'!D26 -> 4 | E31: ='Averaged Data'!E26 -> 1.6 | J31: ='Averaged Data'!J26 -> 29.717892 | K31: ='Averaged Data'!K26 -> 2.5447602 | L31: ='Averaged Data'!L26 -> 1.6057728 | M31: ='Averaged Data'!M26 -> 14.02 | N31: ='Averaged Data'!N26 -> large (or nice) wake pattern | O31: ='Averaged Data'!O26 -> 2.6732155 | P31: ='Averaged Data'!P26 -> 0.70147219 | Q31: ='Averaged Data'!Q26 -> 2.6177715 | ... Z31: ='Averaged Data'!Z26 -> 0.014086144
A33: ='Averaged Data'!A39 -> D2 | B33: ='Averaged Data'!B39 -> V2 | C33: ='Averaged Data'!C39 -> 1 | D33: ='Averaged Data'!D39 -> 0 | E33: ='Averaged Data'!E39 -> 0.4 | J33: ='Averaged Data'!J39 -> 25.708994 | K33: ='Averaged Data'!K39 -> 2.5307477 | L33: ='Averaged Data'!L39 -> 0.39910058 | M33: ='Averaged Data'!M39 -> 13.58 | N33: ='Averaged Data'!N39 -> 0 | O33: ='Averaged Data'!O39 -> 0.027794197 | P33: ='Averaged Data'!P39 -> 0.018148468 | Q33: ='Averaged Data'!Q39 -> 0.027794197 | ... Z33: ='Averaged Data'!Z39 -> 0.0046696618
A34: ='Averaged Data'!A43 -> D2 | B34: ='Averaged Data'!B43 -> V2 | C34: ='Averaged Data'!C43 -> 5 | D34: ='Averaged Data'!D43 -> 8 | E34: ='Averaged Data'!E43 -> 0.4 | J34: ='Averaged Data'!J43 -> 25.702353 | K34: ='Averaged Data'!K43 -> 2.5248251 | L34: ='Averaged Data'!L43 -> 0.40032756 | M34: ='Averaged Data'!M43 -> 15.33 | N34: ='Averaged Data'!N43 -> 0 | O34: ='Averaged Data'!O43 -> 0.06273998 | P34: ='Averaged Data'!P43 -> 0.20249228 | Q34: ='Averaged Data'!Q43 -> 0.03394792 | ... Z34: ='Averaged Data'!Z43 -> 0.053512055
A35: ='Averaged Data'!A49 -> D3 | B35: ='Averaged Data'!B49 -> V2 | C35: ='Averaged Data'!C49 -> 11 | D35: ='Averaged Data'!D49 -> 16 | E35: ='Averaged Data'!E49 -> 0.4 | J35: ='Averaged Data'!J49 -> 19.027666 | K35: ='Averaged Data'!K49 -> 2.5041832 | L35: ='Averaged Data'!L49 -> 0.40042878 | M35: ='Averaged Data'!M49 -> 0 | N35: ='Averaged Data'!N49 -> 0 | O35: ='Averaged Data'!O49 -> 0.1730919 | P35: ='Averaged Data'!P49 -> 0.52700581 | Q35: ='Averaged Data'!Q49 -> 0.021124126 | ... Z35: ='Averaged Data'!Z49 -> 0.14167895
A36: ='Averaged Data'!A53 -> D3 | B36: ='Averaged Data'!B53 -> V2 | C36: ='Averaged Data'!C53 -> 15 | D36: ='Averaged Data'!D53 -> 24 | E36: ='Averaged Data'!E53 -> 0.4 | J36: ='Averaged Data'!J53 -> 19.029286 | K36: ='Averaged Data'!K53 -> 2.5114122 | L36: ='Averaged Data'!L53 -> 0.40032908 | M36: ='Averaged Data'!M53 -> 0 | N36: ='Averaged Data'!N53 -> 0 | O36: ='Averaged Data'!O53 -> 0.46712446 | P36: ='Averaged Data'!P53 -> 0.92867774 | Q36: ='Averaged Data'!Q53 -> 0.049012164 | ... Z36: ='Averaged Data'!Z53 -> 0.2655429
A37: ='Averaged Data'!A40 -> D2 | B37: ='Averaged Data'!B40 -> V2 | C37: ='Averaged Data'!C40 -> 2 | D37: ='Averaged Data'!D40 -> 0 | E37: ='Averaged Data'!E40 -> 0.8 | J37: ='Averaged Data'!J40 -> 25.711423 | K37: ='Averaged Data'!K40 -> 2.5282219 | L37: ='Averaged Data'!L40 -> 0.80760298 | M37: ='Averaged Data'!M40 -> 14.1 | N37: ='Averaged Data'!N40 -> 0 | O37: ='Averaged Data'!O40 -> 0.43268671 | P37: ='Averaged Data'!P40 -> 0.045955954 | Q37: ='Averaged Data'!Q40 -> 0.43268671 | ... Z37: ='Averaged Data'!Z40 -> 0.002887727
A38: ='Averaged Data'!A44 -> D2 | B38: ='Averaged Data'!B44 -> V2 | C38: ='Averaged Data'!C44 -> 6 | D38: ='Averaged Data'!D44 -> 8 | E38: ='Averaged Data'!E44 -> 0.8 | J38: ='Averaged Data'!J44 -> 25.702596 | K38: ='Averaged Data'!K44 -> 2.5228219 | L38: ='Averaged Data'!L44 -> 0.80967196 | M38: ='Averaged Data'!M44 -> 15.47 | N38: ='Averaged Data'!N44 -> 0 | O38: ='Averaged Data'!O44 -> 0.53100439 | P38: ='Averaged Data'!P44 -> 0.80362217 | Q38: ='Averaged Data'!Q44 -> 0.4139941 | ... Z38: ='Averaged Data'!Z44 -> 0.054370446
A39: ='Averaged Data'!A50 -> D3 | B39: ='Averaged Data'!B50 -> V2 | C39: ='Averaged Data'!C50 -> 12 | D39: ='Averaged Data'!D50 -> 16 | E39: ='Averaged Data'!E50 -> 0.8 | J39: ='Averaged Data'!J50 -> 19.026856 | K39: ='Averaged Data'!K50 -> 2.5097573 | L39: ='Averaged Data'!L50 -> 0.81018731 | M39: ='Averaged Data'!M50 -> 0 | N39: ='Averaged Data'!N50 -> 0 | O39: ='Averaged Data'!O50 -> 0.92767938 | P39: ='Averaged Data'!P50 -> 2.2809337 | Q39: ='Averaged Data'!Q50 -> 0.26303212 | ... Z39: ='Averaged Data'!Z50 -> 0.15286213
A40: ='Averaged Data'!A54 -> D3 | B40: ='Averaged Data'!B54 -> V2 | C40: ='Averaged Data'!C54 -> 16 | D40: ='Averaged Data'!D54 -> 24 | E40: ='Averaged Data'!E54 -> 0.8 | J40: ='Averaged Data'!J54 -> 19.029043 | K40: ='Averaged Data'!K54 -> 2.5099315 | L40: ='Averaged Data'!L54 -> 0.80901095 | M40: ='Averaged Data'!M54 -> 0 | N40: ='Averaged Data'!N54 -> 0 | O40: ='Averaged Data'!O54 -> 1.876156 | P40: ='Averaged Data'!P54 -> 3.6966247 | Q40: ='Averaged Data'!Q54 -> 0.21040114 | ... Z40: ='Averaged Data'!Z54 -> 0.25924835
A41: ='Averaged Data'!A56 -> D3 | B41: ='Averaged Data'!B56 -> V2 | C41: ='Averaged Data'!C56 -> 18 | D41: ='Averaged Data'!D56 -> 24 | E41: ='Averaged Data'!E56 -> 1 | J41: ='Averaged Data'!J56 -> 19.027423 | K41: ='Averaged Data'!K56 -> 2.5081025 | L41: ='Averaged Data'!L56 -> 1.0031924 | M41: ='Averaged Data'!M56 -> 14.12 | N41: ='Averaged Data'!N56 -> 0 | O41: ='Averaged Data'!O56 -> 3.0296824 | P41: ='Averaged Data'!P56 -> 5.716538 | Q41: ='Averaged Data'!Q56 -> 0.44262714 | ... Z41: ='Averaged Data'!Z56 -> 0.26285188
A42: ='Averaged Data'!A41 -> D2 | B42: ='Averaged Data'!B41 -> V2 | C42: ='Averaged Data'!C41 -> 3 | D42: ='Averaged Data'!D41 -> 0 | E42: ='Averaged Data'!E41 -> 1.2 | J42: ='Averaged Data'!J41 -> 25.706726 | K42: ='Averaged Data'!K41 -> 2.5298767 | L42: ='Averaged Data'!L41 -> 1.1963631 | M42: ='Averaged Data'!M41 -> 14.27 | N42: ='Averaged Data'!N41 -> 0 | O42: ='Averaged Data'!O41 -> 0.82467747 | P42: ='Averaged Data'!P41 -> 0.11392364 | Q42: ='Averaged Data'!Q41 -> 0.82467747 | ... Z42: ='Averaged Data'!Z41 -> 0.0032621056
A43: ='Averaged Data'!A45 -> D2 | B43: ='Averaged Data'!B45 -> V2 | C43: ='Averaged Data'!C45 -> 7 | D43: ='Averaged Data'!D45 -> 8 | E43: ='Averaged Data'!E45 -> 1.2 | J43: ='Averaged Data'!J45 -> 25.702596 | K43: ='Averaged Data'!K45 -> 2.523867 | L43: ='Averaged Data'!L45 -> 1.1992925 | M43: ='Averaged Data'!M45 -> 0 | N43: ='Averaged Data'!N45 -> 0 | O43: ='Averaged Data'!O45 -> 0.95143993 | P43: ='Averaged Data'!P45 -> 2.0535953 | Q43: ='Averaged Data'!Q45 -> 0.65637535 | ... Z43: ='Averaged Data'!Z45 -> 0.061719634
